Workbook

Sheet Sheet1
G2: EXCEL function VLOOKUP, HLOOKUP & IF ELSE
A3: Name: Harshita Pandey
A5: VLOOKUP QUESTIONS :
A7: Question 1] | B7: Using VLOOKUP, find the Salary of “Yuvraj Patel”.
A9: Answer] | B9: =VLOOKUP("Yuvraj Patel", Employee_bonus!$B$2:$G$51, 6, FALSE) -> 87003 | D9: ie. The salary of Yuvraj Patel is Rs. 87003.
D10: Formula used: | F10: "=VLOOKUP(lookup_value, table_array, Col_index, FALSE)"
A13: Question 2] | B13: Using VLOOKUP, return the Department of Emp_ID = 1031.
A15: Answer] | B15: =VLOOKUP(1031, Employee_bonus!$A$1:$C$51, 3, FALSE) -> Finance | D15: ie. The department of emp_id = 1031 is Finance.
D16: Formula used: | F16: "=VLOOKUP(lookup_value, table_array, col_index, FALSE)"
A20: Question 3] | B20: Use VLOOKUP to find the City of “Sneha Chakraborty”.
A22: Answer] | B22: =VLOOKUP("Sneha Chakraborty", Employee_bonus!$B$1:$E$51, 4, FALSE) -> Delhi | D22: ie. Sneha Chakraborty lives in Delhi.
D23: Formula used: | F23: "=VLOOKUP(lookup_value, table_array, col_index, FALSE)"
A27: Question 4] | B27: Using VLOOKUP, fetch the Score for Emp_ID = 1050.
A29: Answer] | B29: =VLOOKUP(1050, Employee_bonus!$A$1:$D$51, 4, FALSE) -> 84 | D29: ie. The score emp_id = 1050 scored is 84.
D30: Formula used: | F30: "=VLOOKUP(lookup_value, table_array, col_index, FALSE)"
A34: Question 5] | B34: VLOOKUP: Find the Bonus_Eligible status of “Tara Chawla”.
A36: Answer] | B36: =VLOOKUP("Tara Chawla", Employee_bonus!$B$1:$F$51, 5, FALSE) -> No | D36: ie. Tara is not eligible.
D37: Formula used: | F37: "=VLOOKUP(lookup_value, table_array, col_index, FALSE)"
A41: HLOOKUP QUESTIONS :
A43: Question 6] | B43: Convert the dataset horizontally and use HLOOKUP to return the Salary of Emp_ID = 1020.
A45: Answer] | B45: =HLOOKUP(1020, Sheet3!A1:AC7, 7, FALSE) -> 71717 | D45: ie. The salary of emp_id = 1020 is 71717.
D46: Formula used: | F46: "=HLOOKUP(lookup_value, table_array, row_index, FALSE)"
A50: Question 7] | B50: Using HLOOKUP, retrieve the Department value for Emp_ID = 1044.
A52: Answer] | B52: =HLOOKUP(1044, Sheet3!A1:AC7, 3, FALSE) -> #N/A | D52: emp_ID 1044 is not available in the given dataset (Employee_bonus.csv), therefore HLOOKUP correctly returns #N/A.
A56: IF QUESTIONS :
A58: Question 8] | B58: IF for Salary Category: If Salary ≥ 70,000 → “High Salary” Else → “Regular Salary”.
A60: Answer] | B60: =IF(Employee_bonus!G2>=70000,"High Salary", "Regular Salary") -> Regular Salary
A64: IF + AND QUESTIONS :
A66: Question 9] | B66: Rating: Score ≥ 85 and Salary ≥ 60,000 Else return “Average Performer”.
A68: Answer] | B68: example preview: | D68: Score | E68: Salary | F68: Performance Category
D69: 67 | E69: 38545 | F69: =IF(AND(Table1[[#This Row],[Score]]>=85, Table1[[#This Row],[Salary]]>=60000), "Top Performer", "Average Performer") -> Average Performer
D70: 86 | E70: 91199 | F70: =IF(AND(Table1[[#This Row],[Score]]>=85, Table1[[#This Row],[Salary]]>=60000), "Top Performer", "Average Performer") -> Top Performer
D71: 99 | E71: 59766 | F71: =IF(AND(Table1[[#This Row],[Score]]>=85, Table1[[#This Row],[Salary]]>=60000), "Top Performer", "Average Performer") -> Average Performer
D72: 46 | E72: 86087 | F72: =IF(AND(Table1[[#This Row],[Score]]>=85, Table1[[#This Row],[Salary]]>=60000), "Top Performer", "Average Performer") -> Average Performer
D73: 83 | E73: 93840 | F73: =IF(AND(Table1[[#This Row],[Score]]>=85, Table1[[#This Row],[Salary]]>=60000), "Top Performer", "Average Performer") -> Average Performer
D74: 47 | E74: 79384 | F74: =IF(AND(Table1[[#This Row],[Score]]>=85, Table1[[#This Row],[Salary]]>=60000), "Top Performer", "Average Performer") -> Average Performer
D75: 86 | E75: 76005 | F75: =IF(AND(Table1[[#This Row],[Score]]>=85, Table1[[#This Row],[Salary]]>=60000), "Top Performer", "Average Performer") -> Top Performer
D76: 74 | E76: 71576 | F76: =IF(AND(Table1[[#This Row],[Score]]>=85, Table1[[#This Row],[Salary]]>=60000), "Top Performer", "Average Performer") -> Average Performer
D77: 53 | E77: 64353 | F77: =IF(AND(Table1[[#This Row],[Score]]>=85, Table1[[#This Row],[Salary]]>=60000), "Top Performer", "Average Performer") -> Average Performer
D78: 56 | E78: 87003 | F78: =IF(AND(Table1[[#This Row],[Score]]>=85, Table1[[#This Row],[Salary]]>=60000), "Top Performer", "Average Performer") -> Average Performer
...

Sheet Employee_bonus
A1: Emp_id | B1: Name | C1: Department | D1: Score | E1: City | F1: Bonus_Eligible | G1: Salary | H1: Salary Category | I1: Performer Category | J1: Designation | K1: Zone_based Designation
A2: 1001 | B2: Aarav Sharma | C2: Marketing | D2: 67 | E2: Mumbai | F2: Yes | G2: 38545 | H2: =IF(G2>=70000, "High Salary", "Regular Salary") -> Regular Salary | I2: =IF(AND(D2>=85, G2>=60000), "Top Performer", "Average Performer") -> Average Performer | J2: =E2 & " " & C2 & " Staff" -> Mumbai Marketing Staff | K2: =IF(OR(E2="Mumbai",E2="Pune"),"West Zone", IF(E2="Delhi","North Zone", IF(OR(E2="Chennai",E2="Bengaluru"),"South Zone","East Zone"))) & " – " & C2 -> West Zone – Marketing
A3: 1002 | B3: Vivaan Mehta | C3: Operations | D3: 86 | E3: Chennai | F3: No | G3: 91199 | H3: =IF(G3>=70000, "High Salary", "Regular Salary") -> High Salary | I3: =IF(AND(D3>=85, G3>=60000), "Top Performer", "Average Performer") -> Top Performer | J3: =E3 & " " & C3 & " Staff" -> Chennai Operations Staff | K3: =IF(OR(E3="Mumbai",E3="Pune"),"West Zone", IF(E3="Delhi","North Zone", IF(OR(E3="Chennai",E3="Bengaluru"),"South Zone","East Zone"))) & " – " & C3 -> South Zone – Operations
A4: 1003 | B4: Aditya Nair | C4: Finance | D4: 99 | E4: Chennai | F4: Yes | G4: 59766 | H4: =IF(G4>=70000, "High Salary", "Regular Salary") -> Regular Salary | I4: =IF(AND(D4>=85, G4>=60000), "Top Performer", "Average Performer") -> Average Performer | J4: =E4 & " " & C4 & " Staff" -> Chennai Finance Staff | K4: =IF(OR(E4="Mumbai",E4="Pune"),"West Zone", IF(E4="Delhi","North Zone", IF(OR(E4="Chennai",E4="Bengaluru"),"South Zone","East Zone"))) & " – " & C4 -> South Zone – Finance
A5: 1004 | B5: Krishna Rao | C5: Operations | D5: 46 | E5: Mumbai | F5: No | G5: 86087 | H5: =IF(G5>=70000, "High Salary", "Regular Salary") -> High Salary | I5: =IF(AND(D5>=85, G5>=60000), "Top Performer", "Average Performer") -> Average Performer | J5: =E5 & " " & C5 & " Staff" -> Mumbai Operations Staff | K5: =IF(OR(E5="Mumbai",E5="Pune"),"West Zone", IF(E5="Delhi","North Zone", IF(OR(E5="Chennai",E5="Bengaluru"),"South Zone","East Zone"))) & " – " & C5 -> West Zone – Operations
A6: 1005 | B6: Rohan Verma | C6: Operations | D6: 83 | E6: Mumbai | F6: Yes | G6: 93840 | H6: =IF(G6>=70000, "High Salary", "Regular Salary") -> High Salary | I6: =IF(AND(D6>=85, G6>=60000), "Top Performer", "Average Performer") -> Average Performer | J6: =E6 & " " & C6 & " Staff" -> Mumbai Operations Staff | K6: =IF(OR(E6="Mumbai",E6="Pune"),"West Zone", IF(E6="Delhi","North Zone", IF(OR(E6="Chennai",E6="Bengaluru"),"South Zone","East Zone"))) & " – " & C6 -> West Zone – Operations
A7: 1006 | B7: Ishaan Gupta | C7: HR | D7: 47 | E7: Mumbai | F7: Yes | G7: 79384 | H7: =IF(G7>=70000, "High Salary", "Regular Salary") -> High Salary | I7: =IF(AND(D7>=85, G7>=60000), "Top Performer", "Average Performer") -> Average Performer | J7: =E7 & " " & C7 & " Staff" -> Mumbai HR Staff | K7: =IF(OR(E7="Mumbai",E7="Pune"),"West Zone", IF(E7="Delhi","North Zone", IF(OR(E7="Chennai",E7="Bengaluru"),"South Zone","East Zone"))) & " – " & C7 -> West Zone – HR
A8: 1007 | B8: Arjun Kulkarni | C8: Finance | D8: 86 | E8: Mumbai | F8: Yes | G8: 76005 | H8: =IF(G8>=70000, "High Salary", "Regular Salary") -> High Salary | I8: =IF(AND(D8>=85, G8>=60000), "Top Performer", "Average Performer") -> Top Performer | J8: =E8 & " " & C8 & " Staff" -> Mumbai Finance Staff | K8: =IF(OR(E8="Mumbai",E8="Pune"),"West Zone", IF(E8="Delhi","North Zone", IF(OR(E8="Chennai",E8="Bengaluru"),"South Zone","East Zone"))) & " – " & C8 -> West Zone – Finance
A9: 1008 | B9: Kabir Singh | C9: Finance | D9: 74 | E9: Bengaluru | F9: No | G9: 71576 | H9: =IF(G9>=70000, "High Salary", "Regular Salary") -> High Salary | I9: =IF(AND(D9>=85, G9>=60000), "Top Performer", "Average Performer") -> Average Performer | J9: =E9 & " " & C9 & " Staff" -> Bengaluru Finance Staff | K9: =IF(OR(E9="Mumbai",E9="Pune"),"West Zone", IF(E9="Delhi","North Zone", IF(OR(E9="Chennai",E9="Bengaluru"),"South Zone","East Zone"))) & " – " & C9 -> South Zone – Finance
A10: 1009 | B10: Atharv Joshi | C10: Finance | D10: 53 | E10: Pune | F10: No | G10: 64353 | H10: =IF(G10>=70000, "High Salary", "Regular Salary") -> Regular Salary | I10: =IF(AND(D10>=85, G10>=60000), "Top Performer", "Average Performer") -> Average Performer | J10: =E10 & " " & C10 & " Staff" -> Pune Finance Staff | K10: =IF(OR(E10="Mumbai",E10="Pune"),"West Zone", IF(E10="Delhi","North Zone", IF(OR(E10="Chennai",E10="Bengaluru"),"South Zone","East Zone"))) & " – " & C10 -> West Zone – Finance
A11: 1010 | B11: Yuvraj Patel | C11: Operations | D11: 56 | E11: Pune | F11: No | G11: 87003 | H11: =IF(G11>=70000, "High Salary", "Regular Salary") -> High Salary | I11: =IF(AND(D11>=85, G11>=60000), "Top Performer", "Average Performer") -> Average Performer | J11: =E11 & " " & C11 & " Staff" -> Pune Operations Staff | K11: =IF(OR(E11="Mumbai",E11="Pune"),"West Zone", IF(E11="Delhi","North Zone", IF(OR(E11="Chennai",E11="Bengaluru"),"South Zone","East Zone"))) & " – " & C11 -> West Zone – Operations
A12: 1011 | B12: Ananya Iyer | C12: Marketing | D12: 75 | E12: Mumbai | F12: No | G12: 77733 | H12: =IF(G12>=70000, "High Salary", "Regular Salary") -> High Salary | I12: =IF(AND(D12>=85, G12>=60000), "Top Performer", "Average Performer") -> Average Performer | J12: =E12 & " " & C12 & " Staff" -> Mumbai Marketing Staff | K12: =IF(OR(E12="Mumbai",E12="Pune"),"West Zone", IF(E12="Delhi","North Zone", IF(OR(E12="Chennai",E12="Bengaluru"),"South Zone","East Zone"))) & " – " & C12 -> West Zone – Marketing
A13: 1012 | B13: Diya Menon | C13: Finance | D13: 89 | E13: Pune | F13: Yes | G13: 90318 | H13: =IF(G13>=70000, "High Salary", "Regular Salary") -> High Salary | I13: =IF(AND(D13>=85, G13>=60000), "Top Performer", "Average Performer") -> Top Performer | J13: =E13 & " " & C13 & " Staff" -> Pune Finance Staff | K13: =IF(OR(E13="Mumbai",E13="Pune"),"West Zone", IF(E13="Delhi","North Zone", IF(OR(E13="Chennai",E13="Bengaluru"),"South Zone","East Zone"))) & " – " & C13 -> West Zone – Finance
... A51: 1050 | B51: Suresh Pillai | C51: Marketing | D51: 84 | E51: Pune | F51: Yes | G51: 72254 | H51: =IF(G51>=70000, "High Salary", "Regular Salary") -> High Salary | I51: =IF(AND(D51>=85, G51>=60000), "Top Performer", "Average Performer") -> Average Performer | J51: =E51 & " " & C51 & " Staff" -> Pune Marketing Staff | K51: =IF(OR(E51="Mumbai",E51="Pune"),"West Zone", IF(E51="Delhi","North Zone", IF(OR(E51="Chennai",E51="Bengaluru"),"South Zone","East Zone"))) & " – " & C51 -> West Zone – Marketing

Sheet Sheet3
A1: Emp_ID | B1: 1001 | C1: 1002 | D1: 1003 | E1: 1004 | F1: 1005 | G1: 1006 | H1: 1007 | I1: 1008 | J1: 1009 | K1: 1010 | L1: 1011 | M1: 1012 | N1: 1013 | O1: 1014 | P1: 1015 | Q1: 1016 | R1: 1017 | S1: 1018 | T1: 1019 | U1: 1020 | V1: 1021 | W1: 1022 | X1: 1023 | Y1: 1024 | Z1: 1025 | AA1: 1026 | AB1: 1027 | AC1: 1028 | AD1: 1029 | AE1: 1030 | AF1: 1031 | AG1: 1032 | AH1: 1033 | AI1: 1034 | AJ1: 1035 | AK1: 1036 | AL1: 1037 | AM1: 1038 | AN1: 1039 | AO1: 1040 | AP1: 1041 | AQ1: 1042 | AR1: 1043 | AS1: 1044 | AT1: 1045 | AU1: 1046 | AV1: 1047 | AW1: 1048 | AX1: 1049 | AY1: 1050
A2: Name | B2: Aarav Sharma | C2: Vivaan Mehta | D2: Aditya Nair | E2: Krishna Rao | F2: Rohan Verma | G2: Ishaan Gupta | H2: Arjun Kulkarni | I2: Kabir Singh | J2: Atharv Joshi | K2: Yuvraj Patel | L2: Ananya Iyer | M2: Diya Menon | N2: Aadhya Desai | O2: Myra Kapoor | P2: Saanvi Reddy | Q2: Ira Khanna | R2: Meera Bansal | S2: Tara Chawla | T2: Riya Malhotra | U2: Nisha Shah | V2: Siddharth Sinha | W2: Harsh Vardhan | X2: Pranav Chatterjee | Y2: Manav Bhatt | Z2: Dev Goel | AA2: Kunal Saxena | AB2: Ritvik Anand | AC2: Shaurya Tandon | AD2: Ayush Mittal | AE2: Sameer Dubey | AF2: Neha Mishra | AG2: Pooja Agarwal | AH2: Kavya Shetty | AI2: Aarti Singh | AJ2: Juhi Shah | AK2: Simran Kaur | AL2: Tanvi Jha | AM2: Anjali Rana | AN2: Sneha Chakraborty | AO2: Radhika Jain | AP2: Rachit Ahuja | AQ2: Varun Malhotra | AR2: Nikhil Kapoor | AS2: Rahul Suri | AT2: Mohit Batra | AU2: Gaurav Khurana | AV2: Ravi Shukla | AW2: Amit Deshmukh | AX2: Karan Gill | AY2: Suresh Pillai
A3: Department | B3: Marketing | C3: Operations | D3: Finance | E3: Operations | F3: Operations | G3: HR | H3: Finance | I3: Finance | J3: Finance | K3: Operations | L3: Marketing | M3: Finance | N3: Operations | O3: HR | P3: Marketing | Q3: HR | R3: Marketing | S3: Operations | T3: Sales | U3: Marketing | V3: HR | W3: Operations | X3: Marketing | Y3: Sales | Z3: Sales | AA3: Finance | AB3: Finance | AC3: HR | AD3: Marketing | AE3: Marketing | AF3: Finance | AG3: Marketing | AH3: Marketing | AI3: Sales | AJ3: Finance | AK3: Operations | AL3: Finance | AM3: Operations | AN3: Sales | AO3: HR | AP3: Marketing | AQ3: Sales | AR3: Marketing | AS3: HR | AT3: HR | AU3: Sales | AV3: HR | AW3: Operations | AX3: HR | AY3: Marketing
A4: Score | B4: 67 | C4: 86 | D4: 99 | E4: 46 | F4: 83 | G4: 47 | H4: 86 | I4: 74 | J4: 53 | K4: 56 | L4: 75 | M4: 89 | N4: 79 | O4: 43 | P4: 41 | Q4: 45 | R4: 93 | S4: 81 | T4: 43 | U4: 93 | V4: 68 | W4: 57 | X4: 65 | Y4: 83 | Z4: 73 | AA4: 49 | AB4: 75 | AC4: 53 | AD4: 70 | AE4: 87 | AF4: 54 | AG4: 47 | AH4: 53 | AI4: 62 | AJ4: 99 | AK4: 96 | AL4: 79 | AM4: 60 | AN4: 55 | AO4: 84 | AP4: 57 | AQ4: 86 | AR4: 92 | AS4: 63 | AT4: 65 | AU4: 64 | AV4: 99 | AW4: 99 | AX4: 99 | AY4: 84
A5: City | B5: Mumbai | C5: Chennai | D5: Chennai | E5: Mumbai | F5: Mumbai | G5: Mumbai | H5: Mumbai | I5: Bengaluru | J5: Pune | K5: Pune | L5: Mumbai | M5: Pune | N5: Pune | O5: Mumbai | P5: Pune | Q5: Chennai | R5: Delhi | S5: Delhi | T5: Mumbai | U5: Bengaluru | V5: Mumbai | W5: Bengaluru | X5: Delhi | Y5: Mumbai | Z5: Chennai | AA5: Pune | AB5: Bengaluru | AC5: Pune | AD5: Pune | AE5: Mumbai | AF5: Pune | AG5: Chennai | AH5: Pune | AI5: Mumbai | AJ5: Chennai | AK5: Delhi | AL5: Pune | AM5: Mumbai | AN5: Delhi | AO5: Delhi | AP5: Bengaluru | AQ5: Chennai | AR5: Pune | AS5: Mumbai | AT5: Bengaluru | AU5: Chennai | AV5: Bengaluru | AW5: Chennai | AX5: Chennai | AY5: Pune
A6: Bonus_Eligible | B6: Yes | C6: No | D6: Yes | E6: No | F6: Yes | G6: Yes | H6: Yes | I6: No | J6: No | K6: No | L6: No | M6: Yes | N6: No | O6: Yes | P6: Yes | Q6: No | R6: No | S6: No | T6: No | U6: No | V6: No | W6: No | X6: No | Y6: Yes | Z6: No | AA6: No | AB6: Yes | AC6: No | AD6: Yes | AE6: Yes | AF6: No | AG6: Yes | AH6: Yes | AI6: Yes | AJ6: Yes | AK6: No | AL6: Yes | AM6: No | AN6: Yes | AO6: Yes | AP6: Yes | AQ6: Yes | AR6: No | AS6: No | AT6: Yes | AU6: Yes | AV6: No | AW6: Yes | AX6: Yes | AY6: Yes
A7: Salary | B7: 38545 | C7: 91199 | D7: 59766 | E7: 86087 | F7: 93840 | G7: 79384 | H7: 76005 | I7: 71576 | J7: 64353 | K7: 87003 | L7: 77733 | M7: 90318 | N7: 48664 | O7: 92172 | P7: 51736 | Q7: 25854 | R7: 63623 | S7: 32392 | T7: 80680 | U7: 71717 | V7: 75859 | W7: 51309 | X7: 88734 | Y7: 77662 | Z7: 37688 | AA7: 50342 | AB7: 62157 | AC7: 92863 | AD7: 77083 | AE7: 90733 | AF7: 59698 | AG7: 47671 | AH7: 50184 | AI7: 67107 | AJ7: 76663 | AK7: 40708 | AL7: 74811 | AM7: 27811 | AN7: 81250 | AO7: 59754 | AP7: 36411 | AQ7: 27911 | AR7: 92270 | AS7: 33680 | AT7: 36111 | AU7: 62504 | AV7: 26802 | AW7: 33155 | AX7: 64384 | AY7: 72254
